event_id,raw_row_id,ts_recv,ts_event,sequence,action,side,price,size,F_LAST,F_SNAPSHOT,F_MAYBE_BAD_BOOK,bid_px_00,ask_px_00,bid_sz_00,ask_sz_00,canonical_event_id,signed_trade_volume,trade_size,n_records,actions,bid_price_1,ask_price_1,bid_size_1,ask_size_1
0,10125,2026-08-05 13:30:00.001941468+00:00,2026-08-05 13:30:00.001774489+00:00,49583579,A,B,99.23,49,True,False,False,99.3,99.65,550,110,0,0.0,,1,A,99.3,99.65,550,110
1,10126,2026-08-05 13:30:00.018472925+00:00,2026-08-05 13:30:00.018302250+00:00,49594722,A,B,99.3,100,True,False,False,99.3,99.65,650,110,1,0.0,,1,A,99.3,99.65,650,110
2,10127,2026-08-05 13:30:00.028568027+00:00,2026-08-05 13:30:00.028395483+00:00,49608081,A,B,99.3,100,True,False,False,99.3,99.65,750,110,2,0.0,,1,A,99.3,99.65,750,110
3,10128,2026-08-05 13:30:00.052720720+00:00,2026-08-05 13:30:00.052548892+00:00,49632822,T,N,99.43,200,True,False,False,99.3,99.65,750,110,3,0.0,200.0,1,T,99.3,99.65,750,110
4,10129,2026-08-05 13:30:00.055144365+00:00,2026-08-05 13:30:00.054976110+00:00,49635326,A,A,99.59,50,True,False,False,99.3,99.59,750,50,4,0.0,,1,A,99.3,99.59,750,50
5,10130,2026-08-05 13:30:00.061616791+00:00,2026-08-05 13:30:00.061449713+00:00,49641258,C,B,99.3,100,True,False,False,99.3,99.59,650,50,5,0.0,,1,C,99.3,99.59,650,50
6,10131,2026-08-05 13:30:00.061884431+00:00,2026-08-05 13:30:00.061717007+00:00,49641341,A,A,99.53,50,True,False,False,99.3,99.53,650,50,6,0.0,,1,A,99.3,99.53,650,50
7,10132,2026-08-05 13:30:00.061909211+00:00,2026-08-05 13:30:00.061741975+00:00,49641344,C,A,99.59,50,True,False,False,99.3,99.53,650,50,7,0.0,,1,C,99.3,99.53,650,50
8,10133,2026-08-05 13:30:00.061912792+00:00,2026-08-05 13:30:00.061746017+00:00,49641345,A,A,99.5,50,True,False,False,99.3,99.5,650,50,8,0.0,,1,A,99.3,99.5,650,50
9,10134,2026-08-05 13:30:00.062056966+00:00,2026-08-05 13:30:00.061890355+00:00,49641361,C,A,99.53,50,True,False,False,99.3,99.5,650,50,9,0.0,,1,C,99.3,99.5,650,50
10,10135,2026-08-05 13:30:00.062062958+00:00,2026-08-05 13:30:00.061894840+00:00,49641365,A,A,99.44,50,True,False,False,99.3,99.44,650,50,10,0.0,,1,A,99.3,99.44,650,50
11,10136,2026-08-05 13:30:00.062088079+00:00,2026-08-05 13:30:00.061921101+00:00,49641374,A,A,99.5,50,True,False,False,99.3,99.44,650,50,11,0.0,,1,A,99.3,99.44,650,50
12,10137,2026-08-05 13:30:00.062325682+00:00,2026-08-05 13:30:00.062158406+00:00,49641415,C,A,99.5,50,True,False,False,99.3,99.44,650,50,12,0.0,,1,C,99.3,99.44,650,50
13,10138,2026-08-05 13:30:00.062704235+00:00,2026-08-05 13:30:00.062531655+00:00,49641750,C,B,99.3,100,True,False,False,99.3,99.44,550,50,13,0.0,,1,C,99.3,99.44,550,50
14,10139,2026-08-05 13:30:00.068473592+00:00,2026-08-05 13:30:00.068304505+00:00,49649152,C,A,99.8,300,True,False,False,99.3,99.44,550,50,14,0.0,,1,C,99.3,99.44,550,50
15,10140,2026-08-05 13:30:00.070920816+00:00,2026-08-05 13:30:00.070752798+00:00,49652081,A,B,99.15,110,True,False,False,99.3,99.44,550,50,15,0.0,,1,A,99.3,99.44,550,50
16,10141,2026-08-05 13:30:00.081742470+00:00,2026-08-05 13:30:00.081563379+00:00,49664559,A,A,99.44,40,True,False,False,99.3,99.44,550,90,16,0.0,,1,A,99.3,99.44,550,90
17,10142,2026-08-05 13:30:00.082217149+00:00,2026-08-05 13:30:00.082049244+00:00,49665072,A,A,99.8,300,True,False,False,99.3,99.44,550,90,17,0.0,,1,A,99.3,99.44,550,90
18,10143,2026-08-05 13:30:00.089046616+00:00,2026-08-05 13:30:00.088877171+00:00,49672782,C,A,99.8,300,True,False,False,99.3,99.44,550,90,18,0.0,,1,C,99.3,99.44,550,90
19,10144,2026-08-05 13:30:00.089509878+00:00,2026-08-05 13:30:00.089334560+00:00,49673348,T,N,99.43,112,False,False,False,99.3,99.44,550,90,19,0.0,18243.0,4,T,99.3,99.44,550,90
19,10145,2026-08-05 13:30:00.089509878+00:00,2026-08-05 13:30:00.089334560+00:00,49673349,T,N,99.43,2763,False,False,False,99.3,99.44,550,90,19,0.0,18243.0,4,T,99.3,99.44,550,90
19,10146,2026-08-05 13:30:00.089509878+00:00,2026-08-05 13:30:00.089334560+00:00,49673350,T,N,99.43,9914,False,False,False,99.3,99.44,550,90,19,0.0,18243.0,4,T,99.3,99.44,550,90
19,10147,2026-08-05 13:30:00.089509878+00:00,2026-08-05 13:30:00.089334560+00:00,49673351,T,N,99.43,5454,True,False,False,99.3,99.44,550,90,19,0.0,18243.0,4,T,99.3,99.44,550,90
20,10148,2026-08-05 13:30:00.089595612+00:00,2026-08-05 13:30:00.089425857+00:00,49673411,A,A,99.44,50,True,False,False,99.3,99.44,550,140,20,0.0,,1,A,99.3,99.44,550,140
21,10149,2026-08-05 13:30:00.090040857+00:00,2026-08-05 13:30:00.089867143+00:00,49673967,A,A,99.4,50,True,False,False,99.3,99.4,550,50,21,0.0,,1,A,99.3,99.4,550,50
22,10150,2026-08-05 13:30:00.090130503+00:00,2026-08-05 13:30:00.089962053+00:00,49674082,A,B,99.19,49,True,False,False,99.3,99.4,550,50,22,0.0,,1,A,99.3,99.4,550,50
23,10151,2026-08-05 13:30:00.090146967+00:00,2026-08-05 13:30:00.089975957+00:00,49674093,A,A,99.36,50,True,False,False,99.3,99.36,550,50,23,0.0,,1,A,99.3,99.36,550,50
24,10152,2026-08-05 13:30:00.090160803+00:00,2026-08-05 13:30:00.089987585+00:00,49674110,T,A,99.3,500,False,False,False,99.3,99.36,550,50,24,-550.0,550.0,3,CT,99.19,99.36,49,50
24,10153,2026-08-05 13:30:00.090160803+00:00,2026-08-05 13:30:00.089987585+00:00,49674111,T,A,99.3,50,False,False,False,99.3,99.36,50,50,24,-550.0,550.0,3,CT,99.19,99.36,49,50
24,10154,2026-08-05 13:30:00.090160803+00:00,2026-08-05 13:30:00.089987585+00:00,49674111,C,B,99.3,50,True,False,False,99.19,99.36,49,50,24,-550.0,550.0,3,CT,99.19,99.36,49,50
25,10155,2026-08-05 13:30:00.090171297+00:00,2026-08-05 13:30:00.089999554+00:00,49674130,C,A,99.44,50,True,False,False,99.19,99.36,49,50,25,0.0,,1,C,99.19,99.36,49,50
26,10156,2026-08-05 13:30:00.090211685+00:00,2026-08-05 13:30:00.090042085+00:00,49674180,A,A,99.4,50,True,False,False,99.19,99.36,49,50,26,0.0,,1,A,99.19,99.36,49,50
27,10157,2026-08-05 13:30:00.090260131+00:00,2026-08-05 13:30:00.090081833+00:00,49674221,T,B,99.36,50,False,False,False,99.19,99.36,49,50,27,50.0,50.0,2,CT,99.19,99.4,49,100
27,10158,2026-08-05 13:30:00.090260131+00:00,2026-08-05 13:30:00.090081833+00:00,49674221,C,A,99.36,50,True,False,False,99.19,99.4,49,100,27,50.0,50.0,2,CT,99.19,99.4,49,100
28,10159,2026-08-05 13:30:00.090287874+00:00,2026-08-05 13:30:00.090118224+00:00,49674267,A,A,99.36,50,True,False,False,99.19,99.36,49,50,28,0.0,,1,A,99.19,99.36,49,50
29,10160,2026-08-05 13:30:00.090289562+00:00,2026-08-05 13:30:00.090119741+00:00,49674268,A,B,99.19,50,True,False,False,99.19,99.36,99,50,29,0.0,,1,A,99.19,99.36,99,50
30,10161,2026-08-05 13:30:00.090385839+00:00,2026-08-05 13:30:00.090216619+00:00,49674376,A,B,99.27,48,True,False,False,99.27,99.36,48,50,30,0.0,,1,A,99.27,99.36,48,50
31,10162,2026-08-05 13:30:00.090397106+00:00,2026-08-05 13:30:00.090227950+00:00,49674389,A,A,99.35,47,True,False,False,99.27,99.35,48,47,31,0.0,,1,A,99.27,99.35,48,47
32,10163,2026-08-05 13:30:00.090404016+00:00,2026-08-05 13:30:00.090233433+00:00,49674394,C,A,99.4,50,True,False,False,99.27,99.35,48,47,32,0.0,,1,C,99.27,99.35,48,47
33,10164,2026-08-05 13:30:00.090429240+00:00,2026-08-05 13:30:00.090260333+00:00,49674433,C,A,99.36,50,True,False,False,99.27,99.35,48,47,33,0.0,,1,C,99.27,99.35,48,47
34,10165,2026-08-05 13:30:00.090457836+00:00,2026-08-05 13:30:00.090289820+00:00,49674453,C,A,99.4,50,True,False,False,99.27,99.35,48,47,34,0.0,,1,C,99.27,99.35,48,47
35,10166,2026-08-05 13:30:00.090461783+00:00,2026-08-05 13:30:00.090293910+00:00,49674456,A,A,99.35,50,True,False,False,99.27,99.35,48,97,35,0.0,,1,A,99.27,99.35,48,97
36,10167,2026-08-05 13:30:00.090479721+00:00,2026-08-05 13:30:00.090302002+00:00,49674501,C,B,99.27,48,True,False,False,99.19,99.35,99,97,36,0.0,,1,C,99.19,99.35,99,97
37,10168,2026-08-05 13:30:00.090486467+00:00,2026-08-05 13:30:00.090313346+00:00,49674519,C,B,99.19,50,True,False,False,99.19,99.35,49,97,37,0.0,,1,C,99.19,99.35,49,97
38,10169,2026-08-05 13:30:00.090488745+00:00,2026-08-05 13:30:00.090316327+00:00,49674523,A,B,99.36,50,True,False,False,99.27,99.35,50,97,38,0.0,,1,A,99.27,99.35,50,97
39,10170,2026-08-05 13:30:00.090616476+00:00,2026-08-05 13:30:00.090448269+00:00,49674633,A,B,99.2,48,True,False,False,99.27,99.35,50,97,39,0.0,,1,A,99.27,99.35,50,97
40,10171,2026-08-05 13:30:00.090626772+00:00,2026-08-05 13:30:00.090459035+00:00,49674656,A,A,99.33,50,True,False,False,99.27,99.33,50,50,40,0.0,,1,A,99.27,99.33,50,50
41,10172,2026-08-05 13:30:00.090637055+00:00,2026-08-05 13:30:00.090466764+00:00,49674663,C,A,99.36,50,True,False,False,99.27,99.33,50,50,41,0.0,,1,C,99.27,99.33,50,50
42,10173,2026-08-05 13:30:00.090755714+00:00,2026-08-05 13:30:00.090580755+00:00,49674777,C,A,99.35,50,True,False,False,99.27,99.33,50,50,42,0.0,,1,C,99.27,99.33,50,50
43,10174,2026-08-05 13:30:00.090773586+00:00,2026-08-05 13:30:00.090606367+00:00,49674794,A,B,99.27,47,True,False,False,99.27,99.33,97,50,43,0.0,,1,A,99.27,99.33,97,50
44,10175,2026-08-05 13:30:00.090835272+00:00,2026-08-05 13:30:00.090655724+00:00,49674890,C,B,99.27,47,True,False,False,99.27,99.33,50,50,44,0.0,,1,C,99.27,99.33,50,50
45,10176,2026-08-05 13:30:00.090885518+00:00,2026-08-05 13:30:00.090711859+00:00,49674952,A,B,99.2,47,True,False,False,99.27,99.33,50,50,45,0.0,,1,A,99.27,99.33,50,50
46,10177,2026-08-05 13:30:00.091086222+00:00,2026-08-05 13:30:00.090915274+00:00,49675188,C,A,99.33,50,True,False,False,99.27,99.35,50,47,46,0.0,,1,C,99.27,99.35,50,47
47,10178,2026-08-05 13:30:00.091151529+00:00,2026-08-05 13:30:00.090981748+00:00,49675248,A,B,99.28,24,True,False,False,99.28,99.35,24,47,47,0.0,,1,A,99.28,99.35,24,47
48,10179,2026-08-05 13:30:00.091223811+00:00,2026-08-05 13:30:00.091055933+00:00,49675315,A,B,99.22,24,True,False,False,99.28,99.35,24,47,48,0.0,,1,A,99.28,99.35,24,47
49,10180,2026-08-05 13:30:00.091243490+00:00,2026-08-05 13:30:00.091068349+00:00,49675332,T,N,99.34,47,True,False,False,99.28,99.35,24,47,49,0.0,47.0,1,T,99.28,99.35,24,47
50,10181,2026-08-05 13:30:00.091299628+00:00,2026-08-05 13:30:00.091127978+00:00,49675407,A,B,99.28,50,True,False,False,99.28,99.35,74,47,50,0.0,,1,A,99.28,99.35,74,47
51,10182,2026-08-05 13:30:00.095293655+00:00,2026-08-05 13:30:00.095122074+00:00,49678879,C,B,99.2,48,True,False,False,99.28,99.35,74,47,51,0.0,,1,C,99.28,99.35,74,47
52,10183,2026-08-05 13:30:00.095624212+00:00,2026-08-05 13:30:00.095452016+00:00,49679159,C,A,99.35,47,True,False,False,99.28,99.38,74,24,52,0.0,,1,C,99.28,99.38,74,24
53,10184,2026-08-05 13:30:00.095634716+00:00,2026-08-05 13:30:00.095465710+00:00,49679167,C,B,99.2,47,True,False,False,99.28,99.38,74,24,53,0.0,,1,C,99.28,99.38,74,24
54,10185,2026-08-05 13:30:00.095654171+00:00,2026-08-05 13:30:00.095484212+00:00,49679213,A,A,99.36,50,True,False,False,99.28,99.36,74,50,54,0.0,,1,A,99.28,99.36,74,50
55,10186,2026-08-05 13:30:00.100629530+00:00,2026-08-05 13:30:00.100457812+00:00,49684657,C,A,99.38,24,True,False,False,99.28,99.36,74,50,55,0.0,,1,C,99.28,99.36,74,50
56,10187,2026-08-05 13:30:00.101069624+00:00,2026-08-05 13:30:00.100893853+00:00,49685134,C,B,99.28,24,True,False,False,99.28,99.36,50,50,56,0.0,,1,C,99.28,99.36,50,50
57,10188,2026-08-05 13:30:00.101235407+00:00,2026-08-05 13:30:00.101060452+00:00,49685308,C,B,99.22,24,True,False,False,99.28,99.36,50,50,57,0.0,,1,C,99.28,99.36,50,50
58,10189,2026-08-05 13:30:00.112033013+00:00,2026-08-05 13:30:00.111855895+00:00,49696583,A,A,99.68,300,True,False,False,99.28,99.36,50,50,58,0.0,,1,A,99.28,99.36,50,50
59,10190,2026-08-05 13:30:00.113139527+00:00,2026-08-05 13:30:00.112967670+00:00,49698641,C,A,99.72,300,True,False,False,99.28,99.36,50,50,59,0.0,,1,C,99.28,99.36,50,50
60,10191,2026-08-05 13:30:00.113697482+00:00,2026-08-05 13:30:00.113523765+00:00,49699645,A,A,99.43,40,True,False,False,99.28,99.36,50,50,60,0.0,,1,A,99.28,99.36,50,50
61,10192,2026-08-05 13:30:00.113734459+00:00,2026-08-05 13:30:00.113556267+00:00,49699718,C,A,99.44,40,True,False,False,99.28,99.36,50,50,61,0.0,,1,C,99.28,99.36,50,50
62,10193,2026-08-05 13:30:00.121147406+00:00,2026-08-05 13:30:00.120979593+00:00,49712226,A,A,99.4,40,True,False,False,99.28,99.36,50,50,62,0.0,,1,A,99.28,99.36,50,50
63,10194,2026-08-05 13:30:00.121166315+00:00,2026-08-05 13:30:00.120993448+00:00,49712251,C,A,99.43,40,True,False,False,99.28,99.36,50,50,63,0.0,,1,C,99.28,99.36,50,50
64,10195,2026-08-05 13:30:00.121223092+00:00,2026-08-05 13:30:00.121044854+00:00,49712337,A,A,99.36,40,True,False,False,99.28,99.36,50,90,64,0.0,,1,A,99.28,99.36,50,90
65,10196,2026-08-05 13:30:00.121236022+00:00,2026-08-05 13:30:00.121061022+00:00,49712378,C,A,99.4,40,True,False,False,99.28,99.36,50,90,65,0.0,,1,C,99.28,99.36,50,90
66,10197,2026-08-05 13:30:00.121267197+00:00,2026-08-05 13:30:00.121097380+00:00,49712438,C,A,99.36,40,True,False,False,99.28,99.36,50,50,66,0.0,,1,C,99.28,99.36,50,50
67,10198,2026-08-05 13:30:00.121287741+00:00,2026-08-05 13:30:00.121116364+00:00,49712464,A,B,99.27,40,True,False,False,99.28,99.36,50,50,67,0.0,,1,A,99.28,99.36,50,50
68,10199,2026-08-05 13:30:00.121308813+00:00,2026-08-05 13:30:00.121137559+00:00,49712495,A,B,99.22,40,True,False,False,99.28,99.36,50,50,68,0.0,,1,A,99.28,99.36,50,50
69,10200,2026-08-05 13:30:00.124093381+00:00,2026-08-05 13:30:00.123921276+00:00,49717456,C,B,99.22,40,True,False,False,99.28,99.36,50,50,69,0.0,,1,C,99.28,99.36,50,50
70,10201,2026-08-05 13:30:00.125046818+00:00,2026-08-05 13:30:00.124873095+00:00,49719270,A,A,99.35,40,True,False,False,99.28,99.35,50,40,70,0.0,,1,A,99.28,99.35,50,40
71,10202,2026-08-05 13:30:00.125072113+00:00,2026-08-05 13:30:00.124902737+00:00,49719310,C,A,99.36,50,True,False,False,99.28,99.35,50,40,71,0.0,,1,C,99.28,99.35,50,40
72,10203,2026-08-05 13:30:00.125278064+00:00,2026-08-05 13:30:00.125103797+00:00,49719691,A,A,99.33,40,True,False,False,99.28,99.33,50,40,72,0.0,,1,A,99.28,99.33,50,40
73,10204,2026-08-05 13:30:00.125290475+00:00,2026-08-05 13:30:00.125118066+00:00,49719725,C,A,99.35,40,True,False,False,99.28,99.33,50,40,73,0.0,,1,C,99.28,99.33,50,40
74,10205,2026-08-05 13:30:00.125301336+00:00,2026-08-05 13:30:00.125130186+00:00,49719742,T,B,99.33,40,False,False,False,99.28,99.33,50,40,74,40.0,40.0,2,CT,99.28,99.65,50,110
74,10206,2026-08-05 13:30:00.125301336+00:00,2026-08-05 13:30:00.125130186+00:00,49719742,C,A,99.33,40,True,False,False,99.28,99.65,50,110,74,40.0,40.0,2,CT,99.28,99.65,50,110
75,10207,2026-08-05 13:30:00.125317409+00:00,2026-08-05 13:30:00.125144104+00:00,49719765,A,B,99.17,49,True,False,False,99.28,99.65,50,110,75,0.0,,1,A,99.28,99.65,50,110
76,10208,2026-08-05 13:30:00.125338564+00:00,2026-08-05 13:30:00.125164303+00:00,49719801,A,A,99.59,50,True,False,False,99.28,99.59,50,100,76,0.0,,1,A,99.28,99.59,50,100
77,10209,2026-08-05 13:30:00.125517746+00:00,2026-08-05 13:30:00.125348877+00:00,49720091,A,A,99.53,50,True,False,False,99.28,99.53,50,50,77,0.0,,1,A,99.28,99.53,50,50
78,10210,2026-08-05 13:30:00.126084925+00:00,2026-08-05 13:30:00.125912070+00:00,49721101,C,B,99.27,40,True,False,False,99.28,99.53,50,50,78,0.0,,1,C,99.28,99.53,50,50
79,10211,2026-08-05 13:30:00.126106428+00:00,2026-08-05 13:30:00.125933114+00:00,49721130,C,A,99.59,50,True,False,False,99.28,99.53,50,50,79,0.0,,1,C,99.28,99.53,50,50
80,10212,2026-08-05 13:30:00.126121775+00:00,2026-08-05 13:30:00.125951210+00:00,49721156,A,A,99.47,50,True,False,False,99.28,99.47,50,50,80,0.0,,1,A,99.28,99.47,50,50
81,10213,2026-08-05 13:30:00.126351454+00:00,2026-08-05 13:30:00.126180371+00:00,49721523,C,A,99.53,50,True,False,False,99.28,99.47,50,50,81,0.0,,1,C,99.28,99.47,50,50
82,10214,2026-08-05 13:30:00.126362153+00:00,2026-08-05 13:30:00.126191708+00:00,49721531,A,A,99.41,50,True,False,False,99.28,99.41,50,50,82,0.0,,1,A,99.28,99.41,50,50
83,10215,2026-08-05 13:30:00.126430262+00:00,2026-08-05 13:30:00.126256685+00:00,49721609,C,A,99.47,50,True,False,False,99.28,99.41,50,50,83,0.0,,1,C,99.28,99.41,50,50
84,10216,2026-08-05 13:30:00.126723534+00:00,2026-08-05 13:30:00.126549975+00:00,49721990,T,N,99.35,40,True,False,False,99.28,99.41,50,50,84,0.0,40.0,1,T,99.28,99.41,50,50
85,10217,2026-08-05 13:30:00.126853854+00:00,2026-08-05 13:30:00.126682116+00:00,49722220,A,B,99.3,47,True,False,False,99.31,99.41,24,50,85,0.0,,1,A,99.31,99.41,24,50
86,10218,2026-08-05 13:30:00.126867268+00:00,2026-08-05 13:30:00.126697206+00:00,49722245,C,B,99.3,48,True,False,False,99.31,99.41,24,50,86,0.0,,1,C,99.31,99.41,24,50
87,10219,2026-08-05 13:30:00.126912685+00:00,2026-08-05 13:30:00.126741604+00:00,49722300,C,B,99.27,50,True,False,False,99.31,99.41,24,50,87,0.0,,1,C,99.31,99.41,24,50
88,10220,2026-08-05 13:30:00.126914590+00:00,2026-08-05 13:30:00.126743520+00:00,49722302,A,B,99.31,50,True,False,False,99.31,99.41,74,50,88,0.0,,1,A,99.31,99.41,74,50
89,10221,2026-08-05 13:30:00.129073615+00:00,2026-08-05 13:30:00.128904294+00:00,49723590,A,B,99.28,2,True,False,False,99.31,99.41,74,50,89,0.0,,1,A,99.31,99.41,74,50
90,10222,2026-08-05 13:30:00.129084699+00:00,2026-08-05 13:30:00.128917827+00:00,49723594,A,B,99.28,2,True,False,False,99.31,99.41,74,50,90,0.0,,1,A,99.31,99.41,74,50
91,10223,2026-08-05 13:30:00.132382151+00:00,2026-08-05 13:30:00.132215120+00:00,49724454,A,B,99.37,480,True,False,False,99.37,99.41,480,50,91,0.0,,1,A,99.37,99.41,480,50
92,10224,2026-08-05 13:30:00.132404988+00:00,2026-08-05 13:30:00.132238242+00:00,49724457,C,B,99.31,50,True,False,False,99.37,99.41,480,50,92,0.0,,1,C,99.37,99.41,480,50
93,10225,2026-08-05 13:30:00.132408641+00:00,2026-08-05 13:30:00.132240472+00:00,49724458,A,B,99.37,50,True,False,False,99.37,99.41,530,50,93,0.0,,1,A,99.37,99.41,530,50
94,10226,2026-08-05 13:30:00.134099348+00:00,2026-08-05 13:30:00.133923814+00:00,49726558,C,B,99.28,2,True,False,False,99.37,99.41,530,50,94,0.0,,1,C,99.37,99.41,530,50
95,10227,2026-08-05 13:30:00.134139972+00:00,2026-08-05 13:30:00.133962147+00:00,49726636,C,B,99.28,2,True,False,False,99.37,99.41,530,50,95,0.0,,1,C,99.37,99.41,530,50
96,10228,2026-08-05 13:30:00.134913442+00:00,2026-08-05 13:30:00.134742185+00:00,49727413,A,B,99.31,4,True,False,False,99.37,99.41,530,50,96,0.0,,1,A,99.37,99.41,530,50
97,10229,2026-08-05 13:30:00.135190202+00:00,2026-08-05 13:30:00.135017032+00:00,49727816,A,B,99.33,4,True,False,False,99.37,99.41,530,50,97,0.0,,1,A,99.37,99.41,530,50
98,10230,2026-08-05 13:30:00.135227067+00:00,2026-08-05 13:30:00.135050354+00:00,49727884,C,B,99.31,4,True,False,False,99.37,99.41,530,50,98,0.0,,1,C,99.37,99.41,530,50
99,10231,2026-08-05 13:30:00.136865534+00:00,2026-08-05 13:30:00.136693796+00:00,49730296,C,B,99.31,24,True,False,False,99.37,99.41,530,50,99,0.0,,1,C,99.37,99.41,530,50
